nohup: ignoring input
2023-05-29 14:24:12.318485: I tensorflow/core/platform/cpu_feature_guard.cc:142] This TensorFlow binary is optimized with oneAPI Deep Neural Network Library (oneDNN) to use the following CPU instructions in performance-critical operations:  AVX2 AVX512F FMA
To enable them in other operations, rebuild TensorFlow with the appropriate compiler flags.
2023-05-29 14:24:13.257904: I tensorflow/core/common_runtime/gpu/gpu_device.cc:1510] Created device /device:GPU:0 with 43511 MB memory:  -> device: 0, name: NVIDIA A40, pci bus id: 0000:ca:00.0, compute capability: 8.6
2023-05-29 14:24:13.560854: I tensorflow/core/common_runtime/gpu/gpu_device.cc:1510] Created device /job:localhost/replica:0/task:0/device:GPU:0 with 43511 MB memory:  -> device: 0, name: NVIDIA A40, pci bus id: 0000:ca:00.0, compute capability: 8.6
2023-05-29 14:24:19.988395: I tensorflow/compiler/mlir/mlir_graph_optimization_pass.cc:185] None of the MLIR Optimization Passes are enabled (registered 2)
2023-05-29 14:24:52.438814: I tensorflow/stream_executor/cuda/cuda_blas.cc:1760] TensorFloat-32 will be used for the matrix multiplication. This will only be logged once.
Traceback (most recent call last):
  File "c_Main_MsplineN_Z1j.py", line 169, in <module>
    #continue
  File "../../../code/Utils.py", line 210, in sample_save
    n_iters=int(sample_size/iter_size)
  File "/mnt/project_mnt/teo_fs/anaconda3_ml/envs/hreyes-piptf2/lib/python3.8/site-packages/tensorflow/python/eager/def_function.py", line 885, in __call__
    result = self._call(*args, **kwds)
  File "/mnt/project_mnt/teo_fs/anaconda3_ml/envs/hreyes-piptf2/lib/python3.8/site-packages/tensorflow/python/eager/def_function.py", line 933, in _call
    self._initialize(args, kwds, add_initializers_to=initializers)
  File "/mnt/project_mnt/teo_fs/anaconda3_ml/envs/hreyes-piptf2/lib/python3.8/site-packages/tensorflow/python/eager/def_function.py", line 759, in _initialize
    self._stateful_fn._get_concrete_function_internal_garbage_collected(  # pylint: disable=protected-access
  File "/mnt/project_mnt/teo_fs/anaconda3_ml/envs/hreyes-piptf2/lib/python3.8/site-packages/tensorflow/python/eager/function.py", line 3066, in _get_concrete_function_internal_garbage_collected
    graph_function, _ = self._maybe_define_function(args, kwargs)
  File "/mnt/project_mnt/teo_fs/anaconda3_ml/envs/hreyes-piptf2/lib/python3.8/site-packages/tensorflow/python/eager/function.py", line 3463, in _maybe_define_function
    graph_function = self._create_graph_function(args, kwargs)
  File "/mnt/project_mnt/teo_fs/anaconda3_ml/envs/hreyes-piptf2/lib/python3.8/site-packages/tensorflow/python/eager/function.py", line 3298, in _create_graph_function
    func_graph_module.func_graph_from_py_func(
  File "/mnt/project_mnt/teo_fs/anaconda3_ml/envs/hreyes-piptf2/lib/python3.8/site-packages/tensorflow/python/framework/func_graph.py", line 1007, in func_graph_from_py_func
    func_outputs = python_func(*func_args, **func_kwargs)
  File "/mnt/project_mnt/teo_fs/anaconda3_ml/envs/hreyes-piptf2/lib/python3.8/site-packages/tensorflow/python/eager/def_function.py", line 668, in wrapped_fn
    out = weak_wrapped_fn().__wrapped__(*args, **kwds)
  File "/mnt/project_mnt/teo_fs/anaconda3_ml/envs/hreyes-piptf2/lib/python3.8/site-packages/tensorflow/python/framework/func_graph.py", line 994, in wrapper
    raise e.ag_error_metadata.to_exception(e)
TypeError: in user code:


    TypeError: tf__save_bijector_info() takes from 1 to 2 positional arguments but 4 were given


During handling of the above exception, another exception occurred:

Traceback (most recent call last):
  File "c_Main_MsplineN_Z1j.py", line 207, in <module>
    #    X_data_train = MixtureDistributions.inverse_transform_data(X_data_train,V)
TypeError: ResultsToDict() missing 6 required positional arguments: 'eps_regulariser', 'regulariser', 'epochs_input', 'epochs_output', 'training_time', and 'training_device'
Exception ignored in: <function _CheckpointRestoreCoordinatorDeleter.__del__ at 0x7f0373983430>
Traceback (most recent call last):
  File "/mnt/project_mnt/teo_fs/anaconda3_ml/envs/hreyes-piptf2/lib/python3.8/site-packages/tensorflow/python/training/tracking/util.py", line 200, in __del__
TypeError: 'NoneType' object is not callable
